<?xml version="1.0" encoding="utf-8"?>

<robot
  name="wcbot_description" xmlns:xacro="http://www.ros.org/wiki/xacro">
  <xacro:include filename="$(find wcbot_description)/urdf/wcbot.materials.xacro"/>
  <xacro:include filename="$(find wcbot_description)/urdf/wcbot.gazebo.xacro"/>
  <!--<pose>0 0 0.1 0 0 0</pose>-->
  <link
    name="base_link">
    <inertial>
      <origin
	xyz="0 0 0" 
        rpy="0 0 0" />
      <mass
        value="30" />
      <inertia
        ixx="0.0094676"
        ixy="6.731E-06"
        ixz="0.00014715"
        iyy="0.018535"
        iyz="-5.9833E-07"
        izz="0.019464" />
    </inertial>
    <visual>
      <origin
        xyz="0 0 0"
        rpy="0 0 0" />
      <geometry>
        <mesh
          filename="package://wcbot_description/meshes/base_link.STL" />
      </geometry>
      <material name="white">
        <color rgba="1.0 1.0 1.0 1.0"/>
      </material>
    </visual>
    <collision>
      <origin
        xyz="0 0 0"
        rpy="0 0 0" />
      <geometry>
        <mesh
          filename="package://wcbot_description/meshes/base_link.STL" />
      </geometry>
    </collision>
  </link>
  <link
    name="main_R_Link">
    <inertial>
      <origin
        xyz="1.2434E-14 -0.0265 5.5511E-15"
        rpy="0 0 0" />
      <mass
        value="5" />
      <inertia
        ixx="0.0047014"
        ixy="-2.4965E-18"
        ixz="-2.0886E-19"
        iyy="0.0090194"
        iyz="-1.6187E-18"
        izz="0.0047014" />
    </inertial>
    <visual>
      <origin
        xyz="0 0 0"
        rpy="0 0 0" />
      <geometry>
        <mesh
          filename="package://wcbot_description/meshes/main_R_Link.STL" />
      </geometry>
      <material name="grey">
        <color rgba="0.2 0.2 0.2 1.0"/>
      </material>
    </visual>
    <collision>
      <origin
        xyz="0 0 0"
        rpy="1.57075 0 0" />
      <geometry>

        <mesh
          filename="package://wcbot_description/meshes/main_R_Link.STL" />
      </geometry>
    </collision>
  </link>
  <joint
    name="joint_main_R"
    type="continuous">
    <origin
      xyz="0 -0.27021 0"
      rpy="0 0 0" />
    <parent
      link="base_link" />
    <child
      link="main_R_Link" />
    <axis
      xyz="0 1 0" />
  </joint>
  <link
    name="main_L_Link">
    <inertial>
      <origin
        xyz="0 0.0265 2.2204E-16"
        rpy="0 0 0" />
      <mass
        value="5" />
      <inertia
        ixx="0.0047014"
        ixy="-2.4965E-18"
        ixz="-2.0886E-19"
        iyy="0.0090194"
        iyz="-1.6187E-18"
        izz="0.0047014" />
    </inertial>
    <visual>
      <origin
        xyz="0 0 0"
        rpy="0 0 0" />
      <geometry>
        <mesh
          filename="package://wcbot_description/meshes/main_L_Link.STL" />
      </geometry>
      <material name="grey">
        <color rgba="0.2 0.2 0.2 1.0"/>
      </material>
    </visual>
    <collision>
      <origin
        xyz="0 0 0"
        rpy="1.57075 0 0" />
      <geometry>
        <mesh
          filename="package://wcbot_description/meshes/main_L_Link.STL" />
      </geometry>
    </collision>
  </link>
  <joint
    name="joint_main_L"
    type="continuous">
    <origin
      xyz="0 0.27021 0"
      rpy="0 0 0" />
    <parent
      link="base_link" />
    <child
      link="main_L_Link" />
    <axis
      xyz="0 1 0" />
  </joint>
  <link
    name="chair_Link">
    <inertial>
      <origin
        xyz="-0.125 0.00014091 0.43805"
        rpy="0 0 0" />
      <mass
        value="1" />
      <inertia
        ixx="1"
        ixy="-3.8775E-05"
        ixz="0.037619"
        iyy="0.4327"
        iyz="7.136E-05"
        izz="1" />
    </inertial>
    <visual>
      <origin
        xyz="0 0 0"
        rpy="0 0 0" />
      <geometry>
        <mesh
          filename="package://wcbot_description/meshes/chair_Link.STL" />
      </geometry>
      <material name="grey">
        <color rgba="0.2 0.2 0.2 1.0"/>
      </material>
    </visual>
    <collision>
      <origin
        xyz="-0.5 0 -0.09"
        rpy="0 0 0" />
      <geometry>

        <mesh
          filename="package://wcbot_description/meshes/chair_Link.STL" />
      </geometry>
      <surface>
        <friction>
          <ode>
            <mu>0</mu>
            <mu2>0</mu2>
            <slip1>1.0</slip1>
            <slip2>1.0</slip2>
          </ode>
        </friction>
      </surface> 
    </collision>
  </link>
  <joint
    name="joint_chair"
    type="fixed">
    <origin
      xyz="0 0 0"
      rpy="0 0 0" />
    <parent
      link="base_link" />
    <child
      link="chair_Link" />
    <axis
      xyz="0 0 0" />
  </joint>
  <link
    name="spring_Link">
    <inertial>
      <origin
        xyz="-0.1711 0.00011769 0.14125"
        rpy="0 0 0" />
      <mass
        value="0.05" />
      <inertia
        ixx="4.6061E-05"
        ixy="7.5208E-07"
        ixz="-9.4455E-06"
        iyy="4.9446E-05"
        iyz="2.0005E-06"
        izz="2.4445E-05" />
    </inertial>
    <visual>
      <origin
        xyz="0 0 0"
        rpy="0 0 0" />
      <geometry>
        <mesh
          filename="package://wcbot_description/meshes/spring_Link.STL" />
      </geometry>
      <material name="red">
        <color rgba="0.8 0.0 0.0 1.0"/>
      </material>
    </visual>
    <collision>
      <origin
        xyz="0.5 0 -0.09"
        rpy="0 0 0" />
      <geometry>
        <mesh
          filename="package://wcbot_description/meshes/spring_Link.STL" />
      </geometry>
      <surface>
        <friction>
          <ode>
            <mu>0</mu>
            <mu2>0</mu2>
            <slip1>1.0</slip1>
            <slip2>1.0</slip2>
          </ode>
        </friction>
      </surface> 
    </collision>
  </link>
  <joint
    name="joint_spring"
    type="fixed">
    <origin
      xyz="0 0 0"
      rpy="0 0 0" />
    <parent
      link="base_link" />
    <child
      link="spring_Link" />
    <axis
      xyz="0 0 0" />
  </joint>
  <link
    name="caster_fr_Link">
    <inertial>
      <origin
        xyz="-0.36889 0.24887 0.22875"
        rpy="0 0 0" />
      <mass
        value="0.05" />
      <inertia
        ixx="4.6061E-05"
        ixy="4.6061E-05"
        ixz="4.6061E-05"
        iyy="4.6061E-05"
        iyz="-4.6061E-05"
        izz="4.6061E-05" />
    </inertial>
    <visual>
      <origin
        xyz="0 0 0"
        rpy="0 0 0" />
      <geometry>
        <mesh
          filename="package://wcbot_description/meshes/caster_fr_Link.STL" />
      </geometry>
      <material name="black">
        <color rgba="0.0 0.0 0.0 1.0"/>
      </material>
    </visual>
    <collision>
      <origin
        xyz="0.15 0.24887 -0.2"
        rpy="0 0 0" />
      <geometry>
        <mesh
          filename="package://wcbot_description/meshes/caster_fr_Link.STL" />
      </geometry>
    </collision>
  </link>
  <joint
    name="joint_caster_fr"
    type="continuous">    <!--continuous-->
    <origin
      xyz="0.25807 -0.24897 0.10175"
      rpy="0 0 0" />
    <parent
      link="base_link" />
    <child
      link="caster_fr_Link" />
    <axis
      xyz="0 0 1" />
    <dynamics damping="1" friction="0.05"/>
  </joint>
  <link
    name="fr_wheel_Link">
    <inertial>
      <origin
        xyz="-0.3089 0.24887 0.369"
        rpy="0 0 0" />
      <mass
        value="0.05" />
      <inertia
        ixx="4.6061E-05"
        ixy="4.6061E-05"
        ixz="4.6061E-05"
        iyy="4.6061E-05"
        iyz="-4.6061E-05"
        izz="4.6061E-05" />
    </inertial>
    <visual>
      <origin
        xyz="0 0 0"
        rpy="0 0 0" />
      <geometry>
        <mesh
          filename="package://wcbot_description/meshes/fr_wheel_Link.STL" />
      </geometry>
      <material name="white">
        <color rgba="1.0 1.0 1.0 1.0"/>
      </material>
    </visual>
    <collision>
      <origin
        xyz="0 0 0"
        rpy="0 0 0" />
      <geometry>
        <mesh
          filename="package://wcbot_description/meshes/fr_wheel_Link.STL" />
      </geometry>
    </collision>
  </link>
  <joint
    name="joint_fr_wheel"
    type="continuous">    <!--continuous-->
    <origin
      xyz="-0.059986 0 -0.14025"
      rpy="0 0 0" />
    <parent
      link="caster_fr_Link" />
    <child
      link="fr_wheel_Link" />
    <axis
      xyz="0 1 0" />
  </joint>
  <link
    name="caster_fl_Link">
    <inertial>
      <origin
        xyz="-0.36889 -0.24907 0.22941"
        rpy="0 0 0" />
      <mass
        value="0.05" />
      <inertia
        ixx="4.6061E-05"
        ixy="4.6061E-05"
        ixz="4.6061E-05"
        iyy="4.6061E-05"
        iyz="-4.6061E-05"
        izz="4.6061E-05" />
    </inertial>
    <visual>
      <origin
        xyz="0 0 0"
        rpy="0 0 0" />
      <geometry>
        <mesh
          filename="package://wcbot_description/meshes/caster_fl_Link.STL" />
      </geometry>
      <material name="black">
        <color rgba="0.0 0.0 0.0 1.0"/>
      </material>
    </visual>
    <collision>
      <origin
        xyz="0 0 0"
        rpy="0 0 0" />
      <geometry>
        <mesh
          filename="package://wcbot_description/meshes/caster_fl_Link.STL" />
      </geometry>
    </collision>
  </link>
  <joint
    name="joint_caster_fl"
    type="continuous">    <!--continuous-->
    <origin
      xyz="0.25807 0.24897 0.10109"
      rpy="0 0 0" />
    <parent
      link="base_link" />
    <child
      link="caster_fl_Link" />
    <axis
      xyz="0 0 1" />
    <dynamics damping="1" friction="0.05"/>
  </joint>
  <link
    name="fl_wheel_Link">
    <inertial>
      <origin
        xyz="-0.3089 -0.24907 0.369"
        rpy="0 0 0" />
      <mass
        value="0.05" />
      <inertia
        ixx="4.6061E-05"
        ixy="4.6061E-05"
        ixz="4.6061E-05"
        iyy="4.6061E-05"
        iyz="-4.6061E-05"
        izz="4.6061E-05" />
    </inertial>
    <visual>
      <origin
        xyz="0 0 0"
        rpy="0 0 0" />
      <geometry>
        <mesh
          filename="package://wcbot_description/meshes/fl_wheel_Link.STL" />
      </geometry>
      <material name="white">
        <color rgba="1.0 1.0 1.0 1.0"/>
      </material>
    </visual>
    <collision>
      <origin
        xyz="0 0 0"
        rpy="0 0 0" />
      <geometry>
        <mesh
          filename="package://wcbot_description/meshes/fl_wheel_Link.STL" />
      </geometry>
    </collision>
  </link>
  <joint
    name="joint_fl_wheel"
    type="continuous">    <!--continuous-->
    <origin
      xyz="-0.059986 0 -0.13959"
      rpy="0 0 0" />
    <parent
      link="caster_fl_Link" />
    <child
      link="fl_wheel_Link" />
    <axis
      xyz="0 1 0" />
  </joint>
  <link
    name="caster_rr_Link">
    <inertial>
      <origin
        xyz="0.32372 0.17045 0.23246"
        rpy="0 0 0" />
      <mass
        value="0.05" />
      <inertia
        ixx="4.6061E-05"
        ixy="4.6061E-05"
        ixz="4.6061E-05"
        iyy="4.6061E-05"
        iyz="-4.6061E-05"
        izz="4.6061E-05" />
    </inertial>
    <visual>
      <origin
        xyz="0 0 0"
        rpy="0 0 0" />
      <geometry>
        <mesh
          filename="package://wcbot_description/meshes/caster_rr_Link.STL" />
      </geometry>
      <material name="black">
        <color rgba="0.0 0.0 0.0 1.0"/>
      </material>
    </visual>
    <collision>
      <origin
        xyz="0 0.17045 -0.18"
        rpy="0 0 0" />
      <geometry>
        <mesh
          filename="package://wcbot_description/meshes/caster_rr_Link.STL" />
      </geometry>
    </collision>
  </link>
  <joint
    name="joint_caster_rr"
    type="continuous">    <!--continuous-->
    <origin
      xyz="-0.43454 -0.17055 0.098037"
      rpy="0 0 0" />
    <parent
      link="base_link" />
    <child
      link="caster_rr_Link" />
    <axis
      xyz="0 0 1" />
    <dynamics damping="1" friction="0.05"/>
  </joint>
  <link
    name="rr_wheel_Link">
    <inertial>
      <origin
        xyz="0.38371 0.15095 0.369"
        rpy="0 0 0" />
      <mass
        value="0.05" />
      <inertia
        ixx="4.6061E-05"
        ixy="4.6061E-05"
        ixz="4.6061E-05"
        iyy="4.6061E-05"
        iyz="-4.6061E-05"
        izz="4.6061E-05" />
    </inertial>
    <visual>
      <origin
        xyz="0 0 0"
        rpy="0 0 0" />
      <geometry>
        <mesh
          filename="package://wcbot_description/meshes/rr_wheel_Link.STL" />
      </geometry>
      <material name="white">
        <color rgba="1.0 1.0 1.0 1.0"/>
      </material>
    </visual>
    <collision>
      <origin
        xyz="0 0 0"
        rpy="0 0 0" />
      <geometry>
        <mesh
          filename="package://wcbot_description/meshes/rr_wheel_Link.STL" />
      </geometry>
    </collision>
  </link>
  <joint
    name="joint_rr_wheel"
    type="continuous">    <!--continuous-->
    <origin
      xyz="-0.059986 0.0195 -0.13654"
      rpy="0 0 0" />
    <parent
      link="caster_rr_Link" />
    <child
      link="rr_wheel_Link" />
    <axis
      xyz="0 1 0" />
  </joint>
  <link
    name="caster_rl_Link">
    <inertial>
      <origin
        xyz="0.32372 -0.17045 0.23246"
        rpy="0 0 0" />
      <mass
        value="0.05" />
      <inertia
        ixx="4.6061E-05"
        ixy="4.6061E-05"
        ixz="4.6061E-05"
        iyy="4.6061E-05"
        iyz="-4.6061E-05"
        izz="4.6061E-05" />
    </inertial>
    <visual>
      <origin
        xyz="0 0 0"
        rpy="0 0 0" />
      <geometry>
        <mesh
          filename="package://wcbot_description/meshes/caster_rl_Link.STL" />
      </geometry>
      <material name="black">
        <color rgba="0.0 0.0 0.0 1.0"/>
      </material>
    </visual>
    <collision>
      <origin
        xyz="0 0 0"
        rpy="0 0 0" />
      <geometry>
        <mesh
          filename="package://wcbot_description/meshes/caster_rl_Link.STL" />
      </geometry>
    </collision>
  </link>
  <joint
    name="joint_caster_rl"
    type="continuous">    <!--continuous-->
    <origin
      xyz="-0.43454 0.17055 0.097382"
      rpy="0 0 0" />
    <parent
      link="base_link" />
    <child
      link="caster_rl_Link" />
    <axis
      xyz="0 0 1" />
    <dynamics damping="1" friction="0.05"/>
  </joint>
  <link
    name="rl_wheel_Link">
    <inertial>
      <origin
        xyz="0.38371 -0.19015 0.369"
        rpy="0 0 0" />
      <mass
        value="0.05" />
      <inertia
        ixx="4.6061E-05"
        ixy="4.6061E-05"
        ixz="4.6061E-05"
        iyy="4.6061E-05"
        iyz="-4.6061E-05"
        izz="4.6061E-05" />
    </inertial>
    <visual>
      <origin
        xyz="0 0 0"
        rpy="0 0 0" />
      <geometry>
        <mesh
          filename="package://wcbot_description/meshes/rl_wheel_Link.STL" />
      </geometry>
      <material name="white">
        <color rgba="1.0 1.0 1.0 1.0"/>
      </material>
    </visual>
    <collision>
      <origin
        xyz="0 0 0"
        rpy="0 0 0" />
      <geometry>
        <mesh
          filename="package://wcbot_description/meshes/rl_wheel_Link.STL" />
      </geometry>
    </collision>
  </link>
  <joint
    name="joint_rl_wheel"
    type="continuous">    <!---->
    <origin
      xyz="-0.059986 0.0195 -0.13588"
      rpy="0 0 0" />
    <parent
      link="caster_rl_Link" />
    <child
      link="rl_wheel_Link" />
    <axis
      xyz="0 1 0" />
  </joint>



</robot>
